Workbook

Sheet Production
A1: Assumption
A2: capital's share | B2: 0.35 | C2: > standard capital share for small open economies
A3: annual depreciation rate | B3: =AVERAGE('CFC data'!E22:E29) -> 0.0140625 | C3: > 8-year CFC-based depreciation average
K4: HP Filter
D5: K | E5: Real GDP | F5: LnK | G5: LnY | K5: LnZ | L5: LnZ_HP | M5: Second-order difference | N5: LnA-Trend(Check) | O5: objective | P5: =SUMXMY2(K6:K27,L6:L27)+100*SUMSQ(M6:M27) -> 0.050134508
C6: 2002 | D6: =PWT!C14 -> 19350000 | E6: =WEO_Data!C10*1000 -> 1490 | F6: =LN(D6) -> 16.778203 | G6: =LN(E6) -> 7.3065314 | K6: =G6-$B$2*F6 -> 1.4341604 | L6: 1.5223022 | N6: =K6-L6 -> -0.088141865
C7: 2003 | D7: =PWT!C15 -> 19850000 | E7: =WEO_Data!C11*1000 -> 1700 | F7: =LN(D7) -> 16.803715 | G7: =LN(E7) -> 7.4383835 | K7: =G7-$B$2*F7 -> 1.5570834 | L7: 1.590255 | N7: =K7-L7 -> -0.03317161
C8: 2004 | D8: =PWT!C16 -> 20450000 | E8: =WEO_Data!C12*1000 -> 1890 | F8: =LN(D8) -> 16.833493 | G8: =LN(E8) -> 7.5443321 | K8: =G8-$B$2*F8 -> 1.6526094 | L8: 1.6573264 | M8: =L8-2*L7+L6 -> -0.00088141865 | N8: =K8-L8 -> -0.0047170397
C9: 2005 | D9: =PWT!C17 -> 21100000 | E9: =WEO_Data!C13*1000 -> 2160 | F9: =LN(D9) -> 16.864784 | G9: =LN(E9) -> 7.6778635 | K9: =G9-$B$2*F9 -> 1.7751892 | L9: 1.7223033 | M9: =L9-2*L8+L7 -> -0.0020945534 | N9: =K9-L9 -> 0.05288595
C10: 2006 | D10: =PWT!C18 -> 21900000 | E10: =WEO_Data!C14*1000 -> 2320 | F10: =LN(D10) -> 16.901997 | G10: =LN(E10) -> 7.7493225 | K10: =G10-$B$2*F10 -> 1.8336234 | L10: 1.7839253 | M10: =L10-2*L9+L8 -> -0.0033548586 | N10: =K10-L10 -> 0.049698165
C11: 2007 | D11: =PWT!C19 -> 22700000 | E11: =WEO_Data!C15*1000 -> 2560 | F11: =LN(D11) -> 16.937875 | G11: =LN(E11) -> 7.8477625 | K11: =G11-$B$2*F11 -> 1.9195061 | L11: 1.841461 | M11: =L11-2*L10+L9 -> -0.0040863042 | N11: =K11-L11 -> 0.078045152
C12: 2008 | D12: =PWT!C20 -> 23400000 | E12: =WEO_Data!C16*1000 -> 2730 | F12: =LN(D12) -> 16.968247 | G12: =LN(E12) -> 7.9120569 | K12: =G12-$B$2*F12 -> 1.9731706 | L12: 1.8946759 | M12: =L12-2*L11+L10 -> -0.0043207682 | N12: =K12-L12 -> 0.078494701
C13: 2009 | D13: =PWT!C21 -> 23800000 | E13: =WEO_Data!C17*1000 -> 2620 | F13: =LN(D13) -> 16.985196 | G13: =LN(E13) -> 7.8709296 | K13: =G13-$B$2*F13 -> 1.9261109 | L13: 1.944116 | M13: =L13-2*L12+L11 -> -0.0037747807 | N13: =K13-L13 -> -0.018005072
C14: 2010 | D14: =PWT!C22 -> 24000000 | E14: =WEO_Data!C18*1000 -> 2690 | F14: =LN(D14) -> 16.993564 | G14: =LN(E14) -> 7.8972965 | K14: =G14-$B$2*F14 -> 1.9495489 | L14: 1.9911123 | M14: =L14-2*L13+L12 -> -0.0024438461 | N14: =K14-L14 -> -0.041563374
C15: 2011 | D15: =PWT!C23 -> 24300000 | E15: =WEO_Data!C19*1000 -> 2810 | F15: =LN(D15) -> 17.005987 | G15: =LN(E15) -> 7.9409398 | K15: =G15-$B$2*F15 -> 1.9888443 | L15: 2.0368156 | M15: =L15-2*L14+L13 -> -0.0012929623 | N15: =K15-L15 -> -0.047971294
C16: 2012 | D16: =PWT!C24 -> 24700000 | E16: =WEO_Data!C20*1000 -> 3000 | F16: =LN(D16) -> 17.022314 | G16: =LN(E16) -> 8.0063676 | K16: =G16-$B$2*F16 -> 2.0485577 | L16: 2.0819613 | M16: =L16-2*L15+L14 -> -0.00055771226 | N16: =K16-L16 -> -0.033403517
C17: 2013 | D17: =PWT!C25 -> 25200000 | E17: =WEO_Data!C21*1000 -> 3220 | F17: =LN(D17) -> 17.042355 | G17: =LN(E17) -> 8.0771366 | K17: =G17-$B$2*F17 -> 2.1123125 | L17: 2.1268047 | M17: =L17-2*L16+L15 -> -0.00030217512 | N17: =K17-L17 -> -0.014492149
C18: 2014 | D18: =PWT!C26 -> 25800000 | E18: =WEO_Data!C22*1000 -> 3440 | F18: =LN(D18) -> 17.065885 | G18: =LN(E18) -> 8.1432268 | K18: =G18-$B$2*F18 -> 2.170167 | L18: 2.1712675 | M18: =L18-2*L17+L16 -> -0.00038067314 | N18: =K18-L18 -> -0.0011004791
C19: 2015 | D19: =PWT!C27 -> 26500000 | E19: =WEO_Data!C23*1000 -> 3660 | F19: =LN(D19) -> 17.092655 | G19: =LN(E19) -> 8.2052184 | K19: =G19-$B$2*F19 -> 2.2227891 | L19: 2.2151261 | M19: =L19-2*L18+L17 -> -0.00060409267 | N19: =K19-L19 -> 0.0076629378
... C27: 2023 | D27: =PWT!C35 -> 32650000 | E27: =WEO_Data!C31*1000 -> 5520 | F27: =LN(D27) -> 17.301355 | G27: =LN(E27) -> 8.6161331 | K27: =G27-$B$2*F27 -> 2.5606587 | L27: 2.5431563 | M27: =L27-2*L26+L25 -> 0.00017502413 | N27: =K27-L27 -> 0.017502413
D35: K/Y | E35: K | F35: Y | G35: LnZ trend | H35: Ystar_base | I35: Investment | J35: ΔK | K35: K_With | L35: Ystar_with | M35: Uplift | N35: Projected GDP | O35: Projected GDP Growth | P35: Baseline GDP Growth
C36: 2002 | D36: =E36/F36 -> 12986.577 | E36: =D6 -> 19350000 | F36: =WEO_Data!C10*1000 -> 1490 | G36: =L6 -> 1.5223022 | H36: =EXP(G36)*(E36^$B$2) -> 1627.2931 | K36: =E36+J36 -> 19350000 | L36: =EXP(G36)*(K36^$B$2) -> 1627.2931 | M36: =100*(L36/H36-1) -> 0 | N36: =H36*(1+M36/100) -> 1627.2931
C37: 2003 | D37: =E37/F37 -> 11676.471 | E37: =D7 -> 19850000 | F37: =WEO_Data!C11*1000 -> 1700 | G37: =L7 -> 1.590255 | H37: =EXP(G37)*(E37^$B$2) -> 1757.3375 | J37: =(1-$B$3)*J36+I37 -> 0 | K37: =E37+J37 -> 19850000 | L37: =EXP(G37)*(K37^$B$2) -> 1757.3375 | M37: =100*(L37/H37-1) -> 0 | N37: =H37*(1+M37/100) -> 1757.3375 | O37: =100*(N37/N36-1) -> 7.9914505 | P37: =100*(F37/F36-1) -> 14.09396
C38: 2004 | D38: =E38/F38 -> 10820.106 | E38: =D8 -> 20450000 | F38: =WEO_Data!C12*1000 -> 1890 | G38: =L8 -> 1.6573264 | H38: =EXP(G38)*(E38^$B$2) -> 1898.9363 | J38: =(1-$B$3)*J37+I38 -> 0 | K38: =E38+J38 -> 20450000 | L38: =EXP(G38)*(K38^$B$2) -> 1898.9363 | M38: =100*(L38/H38-1) -> 0 | N38: =H38*(1+M38/100) -> 1898.9363 | O38: =100*(N38/N37-1) -> 8.0575757 | P38: =100*(F38/F37-1) -> 11.176471
C39: 2005 | D39: =E39/F39 -> 9768.5185 | E39: =D9 -> 21100000 | F39: =WEO_Data!C13*1000 -> 2160 | G39: =L9 -> 1.7223033 | H39: =EXP(G39)*(E39^$B$2) -> 2048.7345 | J39: =(1-$B$3)*J38+I39 -> 0 | K39: =E39+J39 -> 21100000 | L39: =EXP(G39)*(K39^$B$2) -> 2048.7345 | M39: =100*(L39/H39-1) -> 0 | N39: =H39*(1+M39/100) -> 2048.7345 | O39: =100*(N39/N38-1) -> 7.8885327 | P39: =100*(F39/F38-1) -> 14.285714
C40: 2006 | D40: =E40/F40 -> 9439.6552 | E40: =D10 -> 21900000 | F40: =WEO_Data!C14*1000 -> 2320 | G40: =L10 -> 1.7839253 | H40: =EXP(G40)*(E40^$B$2) -> 2207.5185 | J40: =(1-$B$3)*J39+I40 -> 0 | K40: =E40+J40 -> 21900000 | L40: =EXP(G40)*(K40^$B$2) -> 2207.5185 | M40: =100*(L40/H40-1) -> 0 | N40: =H40*(1+M40/100) -> 2207.5185 | O40: =100*(N40/N39-1) -> 7.7503454 | P40: =100*(F40/F39-1) -> 7.4074074
C41: 2007 | D41: =E41/F41 -> 8867.1875 | E41: =D11 -> 22700000 | F41: =WEO_Data!C15*1000 -> 2560 | G41: =L11 -> 1.841461 | H41: =EXP(G41)*(E41^$B$2) -> 2367.802 | J41: =(1-$B$3)*J40+I41 -> 0 | K41: =E41+J41 -> 22700000 | L41: =EXP(G41)*(K41^$B$2) -> 2367.802 | M41: =100*(L41/H41-1) -> 0 | N41: =H41*(1+M41/100) -> 2367.802 | O41: =100*(N41/N40-1) -> 7.2608021 | P41: =100*(F41/F40-1) -> 10.344828
C42: 2008 | D42: =E42/F42 -> 8571.4286 | E42: =D12 -> 23400000 | F42: =WEO_Data!C16*1000 -> 2730 | G42: =L12 -> 1.8946759 | H42: =EXP(G42)*(E42^$B$2) -> 2523.904 | J42: =(1-$B$3)*J41+I42 -> 0 | K42: =E42+J42 -> 23400000 | L42: =EXP(G42)*(K42^$B$2) -> 2523.904 | M42: =100*(L42/H42-1) -> 0 | N42: =H42*(1+M42/100) -> 2523.904 | O42: =100*(N42/N41-1) -> 6.5926956 | P42: =100*(F42/F41-1) -> 6.640625
C43: 2009 | D43: =E43/F43 -> 9083.9695 | E43: =D13 -> 23800000 | F43: =WEO_Data!C17*1000 -> 2620 | G43: =L13 -> 1.944116 | H43: =EXP(G43)*(E43^$B$2) -> 2667.6005 | J43: =(1-$B$3)*J42+I43 -> 0 | K43: =E43+J43 -> 23800000 | L43: =EXP(G43)*(K43^$B$2) -> 2667.6005 | M43: =100*(L43/H43-1) -> 0 | N43: =H43*(1+M43/100) -> 2667.6005 | O43: =100*(N43/N42-1) -> 5.693423 | P43: =100*(F43/F42-1) -> -4.029304
C44: 2010 | D44: =E44/F44 -> 8921.9331 | E44: =D14 -> 24000000 | F44: =WEO_Data!C18*1000 -> 2690 | G44: =L14 -> 1.9911123 | H44: =EXP(G44)*(E44^$B$2) -> 2804.1615 | J44: =(1-$B$3)*J43+I44 -> 0 | K44: =E44+J44 -> 24000000 | L44: =EXP(G44)*(K44^$B$2) -> 2804.1615 | M44: =100*(L44/H44-1) -> 0 | N44: =H44*(1+M44/100) -> 2804.1615 | O44: =100*(N44/N43-1) -> 5.1192441 | P44: =100*(F44/F43-1) -> 2.6717557
C45: 2011 | D45: =E45/F45 -> 8647.6868 | E45: =D15 -> 24300000 | F45: =WEO_Data!C19*1000 -> 2810 | G45: =L15 -> 2.0368156 | H45: =EXP(G45)*(E45^$B$2) -> 2948.0849 | J45: =(1-$B$3)*J44+I45 -> 0 | K45: =E45+J45 -> 24300000 | L45: =EXP(G45)*(K45^$B$2) -> 2948.0849 | M45: =100*(L45/H45-1) -> 0 | N45: =H45*(1+M45/100) -> 2948.0849 | O45: =100*(N45/N44-1) -> 5.1324933 | P45: =100*(F45/F44-1) -> 4.4609665
C46: 2012 | D46: =E46/F46 -> 8233.3333 | E46: =D16 -> 24700000 | F46: =WEO_Data!C20*1000 -> 3000 | G46: =L16 -> 2.0819613 | H46: =EXP(G46)*(E46^$B$2) -> 3101.903 | J46: =(1-$B$3)*J45+I46 -> 0 | K46: =E46+J46 -> 24700000 | L46: =EXP(G46)*(K46^$B$2) -> 3101.903 | M46: =100*(L46/H46-1) -> 0 | N46: =H46*(1+M46/100) -> 3101.903 | O46: =100*(N46/N45-1) -> 5.2175608 | P46: =100*(F46/F45-1) -> 6.7615658
C47: 2013 | D47: =E47/F47 -> 7826.087 | E47: =D17 -> 25200000 | F47: =WEO_Data!C21*1000 -> 3220 | G47: =L17 -> 2.1268047 | H47: =EXP(G47)*(E47^$B$2) -> 3267.0045 | J47: =(1-$B$3)*J46+I47 -> 0 | K47: =E47+J47 -> 25200000 | L47: =EXP(G47)*(K47^$B$2) -> 3267.0045 | M47: =100*(L47/H47-1) -> 0 | N47: =H47*(1+M47/100) -> 3267.0045 | O47: =100*(N47/N46-1) -> 5.3225861 | P47: =100*(F47/F46-1) -> 7.3333333
C48: 2014 | D48: =E48/F48 -> 7500 | E48: =D18 -> 25800000 | F48: =WEO_Data!C22*1000 -> 3440 | G48: =L18 -> 2.1712675 | H48: =EXP(G48)*(E48^$B$2) -> 3443.7877 | J48: =(1-$B$3)*J47+I48 -> 0 | K48: =E48+J48 -> 25800000 | L48: =EXP(G48)*(K48^$B$2) -> 3443.7877 | M48: =100*(L48/H48-1) -> 0 | N48: =H48*(1+M48/100) -> 3443.7877 | O48: =100*(N48/N47-1) -> 5.4111721 | P48: =100*(F48/F47-1) -> 6.8322981
... C57: 2023 | D57: =E57/F57 -> 5914.8551 | E57: =D27 -> 32650000 | F57: =WEO_Data!C31*1000 -> 5520 | G57: =L27 -> 2.5431563 | H57: =EXP(G57)*(E57^$B$2) -> 5424.2273 | J57: =(1-$B$3)*J56+I57 -> 0 | K57: =E57+J57 -> 32650000 | L57: =EXP(G57)*(K57^$B$2) -> 5424.2273 | M57: =100*(L57/H57-1) -> 0 | N57: =H57*(1+M57/100) -> 5424.2273 | O57: =100*(N57/N56-1) -> 5.1386807 | P57: =100*(F57/F56-1) -> 6.5637066
C58: 2024 | E58: =F58*AVERAGE(D$49:D$57) -> 39485018 | F58: =WEO_Data!C32*1000 -> 5960 | G58: {=TREND(L$6:L$27,C$6:C$27,C58)} -> 2.6241773 | H58: =EXP(G58)*(E58^$B$2) -> 6286.6175 | J58: =(1-$B$3)*J57+I58 -> 0 | K58: =E58+J58 -> 39485018 | L58: =EXP(G58)*(K58^$B$2) -> 6286.6175 | M58: =100*(L58/H58-1) -> 0 | N58: =H58*(1+M58/100) -> 6286.6175 | O58: =100*(N58/N57-1) -> 15.898859 | P58: =100*(F58/F57-1) -> 7.9710145
C59: 2025 | E59: =F59*AVERAGE(D$49:D$57) -> 41870019 | F59: =WEO_Data!C33*1000 -> 6320 | G59: {=TREND(L$6:L$27,C$6:C$27,C59)} -> 2.6713839 | H59: =EXP(G59)*(E59^$B$2) -> 6727.1856 | J59: =(1-$B$3)*J58+I59 -> 0 | K59: =E59+J59 -> 41870019 | L59: =EXP(G59)*(K59^$B$2) -> 6727.1856 | M59: =100*(L59/H59-1) -> 0 | N59: =H59*(1+M59/100) -> 6727.1856 | O59: =100*(N59/N58-1) -> 7.0080312 | P59: =100*(F59/F58-1) -> 6.0402685
C60: 2026 | E60: =F60*AVERAGE(D$49:D$57) -> 44387520 | F60: =WEO_Data!C34*1000 -> 6700 | G60: {=TREND(L$6:L$27,C$6:C$27,C60)} -> 2.7185906 | H60: =EXP(G60)*(E60^$B$2) -> 7197.9728 | I60: =Investment!C2 -> 176050 | J60: =(1-$B$3)*J59+I60 -> 176050 | K60: =E60+J60 -> 44563570 | L60: =EXP(G60)*(K60^$B$2) -> 7207.952 | M60: =100*(L60/H60-1) -> 0.13863862 | N60: =H60*(1+M60/100) -> 7207.952 | O60: =100*(N60/N59-1) -> 7.1466195 | P60: =100*(F60/F59-1) -> 6.0126582
C61: 2027 | E61: =F61*AVERAGE(D$49:D$57) -> 47037521 | F61: =WEO_Data!C35*1000 -> 7100 | G61: {=TREND(L$6:L$27,C$6:C$27,C61)} -> 2.7657972 | H61: =EXP(G61)*(E61^$B$2) -> 7700.626 | I61: =Investment!C3 -> 251500 | J61: =(1-$B$3)*J60+I61 -> 425074.3 | K61: =E61+J61 -> 47462595 | L61: =EXP(G61)*(K61^$B$2) -> 7724.9112 | M61: =100*(L61/H61-1) -> 0.31536783 | N61: =H61*(1+M61/100) -> 7724.9112 | O61: =100*(N61/N60-1) -> 7.1720691 | P61: =100*(F61/F60-1) -> 5.9701493
C62: 2028 | E62: =F62*AVERAGE(D$49:D$57) -> 49859772 | F62: =WEO_Data!C36*1000 -> 7526 | G62: {=TREND(L$6:L$27,C$6:C$27,C62)} -> 2.8130039 | H62: =EXP(G62)*(E62^$B$2) -> 8239.1929 | I62: =Investment!C4 -> 326950 | J62: =(1-$B$3)*J61+I62 -> 746046.69 | K62: =E62+J62 -> 50605819 | L62: =EXP(G62)*(K62^$B$2) -> 8282.1335 | M62: =100*(L62/H62-1) -> 0.52117546 | N62: =H62*(1+M62/100) -> 8282.1335 | O62: =100*(N62/N61-1) -> 7.213316 | P62: =100*(F62/F61-1) -> 6
...

Sheet Investment
B1: Year | C1: Project Investment (Deflated)
B2: 2026 | C2: 176050
B3: 2027 | C3: 251500
B4: 2028 | C4: 326950
B5: 2029 | C5: 402400
B6: 2030 | C6: 427550
B7: 2031 | C7: 377250
B8: 2032 | C8: 301800
B9: 2033 | C9: 251500

Sheet CFC data
A1: DATE | B1: TIME PERIOD | C1: Consumption of fixed capital (IDCM.A.N.AM.W2.S1.S1.D.P51C.N1G._T._Z.XDC.V.N) | D1: Capital Stock | E1: Depreciation rate
A2: 35430 | B2: 1996 | C2: 403700000000 | D2: =PWT!C8 -> 18350000 | E2: =C2/1000000/D2 -> 0.022
A3: 35795 | B3: 1997 | C3: 392375000000 | D3: =PWT!C9 -> 18250000 | E3: =C3/1000000/D3 -> 0.0215
A4: 36160 | B4: 1998 | C4: 384300000000 | D4: =PWT!C10 -> 18300000 | E4: =C4/1000000/D4 -> 0.021
A5: 36525 | B5: 1999 | C5: 378225000000 | D5: =PWT!C11 -> 18450000 | E5: =C5/1000000/D5 -> 0.0205
A6: 36891 | B6: 2000 | C6: 373000000000 | D6: =PWT!C12 -> 18650000 | E6: =C6/1000000/D6 -> 0.02
A7: 37256 | B7: 2001 | C7: 369525000000 | D7: =PWT!C13 -> 18950000 | E7: =C7/1000000/D7 -> 0.0195
A8: 37621 | B8: 2002 | C8: 367650000000 | D8: =PWT!C14 -> 19350000 | E8: =C8/1000000/D8 -> 0.019
A9: 37986 | B9: 2003 | C9: 367225000000 | D9: =PWT!C15 -> 19850000 | E9: =C9/1000000/D9 -> 0.0185
A10: 38352 | B10: 2004 | C10: 368100000000 | D10: =PWT!C16 -> 20450000 | E10: =C10/1000000/D10 -> 0.018
A11: 38717 | B11: 2005 | C11: 375580000000 | D11: =PWT!C17 -> 21100000 | E11: =C11/1000000/D11 -> 0.0178
A12: 39082 | B12: 2006 | C12: 383250000000 | D12: =PWT!C18 -> 21900000 | E12: =C12/1000000/D12 -> 0.0175
A13: 39447 | B13: 2007 | C13: 385900000000 | D13: =PWT!C19 -> 22700000 | E13: =C13/1000000/D13 -> 0.017
... A29: 45291 | B29: 2023 | C29: 430980000000 | D29: =PWT!C35 -> 32650000 | E29: =C29/1000000/D29 -> 0.0132

Sheet PWT
A1: year | B1: rgdpna | C1: rnna
A2: 1990 | B2: 1660000 | C2: 20800000
A3: 1991 | B3: 1520000 | C3: 20400000
A4: 1992 | B4: 1200000 | C4: 19800000
A5: 1993 | B5: 970000 | C5: 19200000
A6: 1994 | B6: 890000 | C6: 18800000
A7: 1995 | B7: 940000 | C7: 18500000
A8: 1996 | B8: 1010000 | C8: 18350000
A9: 1997 | B9: 1080000 | C9: 18250000
A10: 1998 | B10: 1150000 | C10: 18300000
A11: 1999 | B11: 1190000 | C11: 18450000
A12: 2000 | B12: 1240000 | C12: 18650000
A13: 2001 | B13: 1330000 | C13: 18950000
... A35: 2023 | B35: 5520000 | C35: 32650000

Sheet WEO_Data
B1: WEO Country Code | C1: 911 | D1: 911
B2: WEO Subject Code | C2: NGDP_R | D2: NGDP_RPCH
B3: Country | C3: Armenia | D3: Armenia
B4: Subject Descriptor | C4: Gross domestic product, constant prices | D4: Gross domestic product, constant prices
B5: Units | C5: National currency | D5: Percent change
B6: Scale | C6: Billions | D6: Units
B7: Country/Series-specific Notes | C7: Source: National Statistical Service of the Republic of Armenia. Base year: 2019. Primary domestic currency: Armenian dram. Data updated: 04/2025 | D7: See notes for: Gross domestic product, constant prices (National currency).
B8: 2000 | C8: 1.24 | D8: 5.9
B9: 2001 | C9: 1.33 | D9: 9.6
B10: 2002 | C10: 1.49 | D10: 13.2
B11: 2003 | C11: 1.7 | D11: 13.6
B12: 2004 | C12: 1.89 | D12: 11.1
B13: 2005 | C13: 2.16 | D13: 14
B14: 2006 | C14: 2.32 | D14: 7.6
B15: 2007 | C15: 2.56 | D15: 10.4
B16: 2008 | C16: 2.73 | D16: 6.9
B17: 2009 | C17: 2.62 | D17: -4.1
B18: 2010 | C18: 2.69 | D18: 2.6
B19: 2011 | C19: 2.81 | D19: 4.3
... B35: 2027 | C35: 7.1 | D35: 6
B36: 2028 | C36: =C35*(1+D36/100) -> 7.526 | D36: 6
B37: 2029 | C37: =C36*(1+D37/100) -> 7.97756 | D37: 6
B38: 2030 | C38: =C37*(1+D38/100) -> 8.4562136 | D38: 6
B39: 2031 | C39: =C38*(1+D39/100) -> 8.9635864 | D39: 6
B40: 2032 | C40: =C39*(1+D40/100) -> 9.5014016 | D40: 6
B41: 2033 | C41: =C40*(1+D41/100) -> 10.071486 | D41: 6
B42: 2034 | C42: =C41*(1+D42/100) -> 10.675775 | D42: 6
B43: 2035 | C43: =C42*(1+D43/100) -> 11.316321 | D43: 6
B44: 2036 | C44: =C43*(1+D44/100) -> 11.995301 | D44: 6
B45: 2037 | C45: =C44*(1+D45/100) -> 12.715019 | D45: 6
B46: 2038 | C46: =C45*(1+D46/100) -> 13.47792 | D46: 6
B47: 2039 | C47: =C46*(1+D47/100) -> 14.286595 | D47: 6
... B51: 2043 | C51: =C50*(1+D51/100) -> 18.036497 | D51: 6
